Workbook

Sheet Main 2015
B1: Project Sponsor | C1: Project Name | D1: Amt Request | E1: Amt Approved | F1: Total Score | G1: Amt Awarded | H1: Source | I1: Category | J1: Comments | K1: District | L1: County
B2: Chattahoochee Hills, City of | C2: Trails of Chattahoochee Hills | D2: 100000 | E2: 100000 | F2: 165 | G2: 100000 | I2: Comb Non | K2: 13 | L2: Fulton
B3: Georgia College & State University | C3: Fishing Creek Community Trail: Campus Connector | D3: 100000 | E3: 100000 | F3: 160 | G3: 100000 | I3: Comb Non | J3: Concerns about public being able to access campus trail | K3: 10 | L3: Baldwin
B4: Perry, City of | C4: Big Indian Creek Waterway Trail Phase IV | D4: 100000 | E4: 100000 | F4: 155 | G4: 100000 | I4: Comb Non | K4: 8 | L4: Houston
B5: Ringgold, City of | C5: Trail of Tears Phase II | D5: 100000 | E5: 100000 | F5: 155 | G5: 100000 | I5: Comb Non | K5: 9 | L5: Catoosa
B6: Dawsonville, City of | C6: Main Street Park Trail | D6: 100000 | E6: 100000 | F6: 145 | G6: 100000 | I6: Comb Non | K6: 9 | L6: Dawson
B7: Maxeys, City of | C7: Firefly Trail | D7: 100000 | E7: 100000 | F7: 145 | G7: 100000 | I7: Comb Non | K7: 10 | L7: Oglethorpe
B8: Lee County | C8: Rails to Trails - Lee County Trailheads | D8: 100000 | E8: 100000 | F8: 140 | G8: =E8 -> 100000 | I8: Comb Non | J8: If funded, applicant needs to show proof that this project connects to existing rails to trails project | K8: 2 | L8: Lee
B9: White County | C9: Yonah Preserve Multi-Use Trail Phase II | D9: 100000 | E9: 100000 | F9: 140 | G9: =E9 -> 100000 | I9: Comb Non | K9: 9 | L9: White
B10: Bibb County/City of Macon | C10: Amerson Water Works and Ocmulgee Heritage Trail Connector | D10: 100000 | E10: 92000 | F10: 130 | G10: =E10 -> 92000 | I10: Comb Non | K10: 2 | L10: Macon/Bibb
B11: Eatonton, City of | C11: Briar Patch Trail Phase II | D11: 99748.67 | E11: 99748.67 | F11: 125 | I11: Comb Non | K11: 10 | L11: Putnam
B12: Fayetteville, City of | C12: The Ridge Nature Area Trails | D12: 99740 | E12: 97240 | F12: 125 | I12: Comb Non | K12: 8 | L12: Fayette
B13: Gainesville, City of | C13: Midtown Greenway Airport Multi-Use Trail | D13: 100000 | E13: 100000 | F13: 125 | I13: Comb Non | K13: 9 | L13: Hall
B14: Hiawassee, City of | C14: Mayor's Park Trail | D14: 50000 | E14: 50000 | F14: 125 | I14: Comb Non | J14: City does not own land, in long-term agreement with TVA | K14: 9 | L14: Towns
B15: Jasper, City of | C15: The North Railroad Trail Project | D15: 100000 | E15: 100000 | F15: 125 | I15: Comb Non | K15: 9 | L15: Pickens
B16: Augusta Canal Authority | C16: Raw Water Pumping Station Trailhead | D16: 100000 | E16: 100000 | F16: 120 | I16: Comb Non | K16: 12 | L16: Richmond
B17: Troup County | C17: Eastside Park Trail | D17: 100000 | E17: 100000 | F17: 120 | I17: Comb Non | K17: 3 | L17: Troup
B18: Milledgeville, City of | C18: Fishing Creek Community Trail Downtown Connector Maintenance Access | D18: 94820 | E18: 94820 | F18: 115 | I18: Comb Non | J18: Concerns about trailhead parking in grocery store lot | K18: 10 | L18: Baldwin
B19: Thomasville, City of | C19: Thomasville Community Landmarks Trail | D19: 100000 | E19: 100000 | F19: 115 | I19: Comb Non | K19: 8 | L19: Thomas
B20: Atlanta, City of | C20: Atlanta BeltLine Trailhead at 1385 Raplh David Abernathy Blvd | D20: 100000 | E20: 100000 | F20: 110 | I20: Comb Non | K20: 5 | L20: Fulton
B21: Jones County | C21: Highway 49 Recreational Trail | D21: 92728 | E21: 92728 | F21: 110 | I21: Comb Non | K21: 8 | L21: Jones
B22: Toccoa, City of | C22: Lake Toccoa Recreational Trail | D22: 100000 | E22: 100000 | F22: 100 | I22: Comb Non | K22: 9 | L22: Stephens
B23: Trion, Town of | C23: Park Avenue Trail Phase II | D23: 100000 | E23: 100000 | F23: 100 | I23: Comb Non | J23: Questions about school's contribution to project, not clearly outlined | K23: 11 | L23: Chattooga
B24: Cedartown, City of | C24: Big Spring Cherokee Heritage Trail | D24: 100000 | E24: 100000 | F24: 90 | I24: Comb Non | K24: 14 | L24: Polk
B25: Gwinnett County | C25: Sweetwater Creek Greenway Trailhead | D25: 100000 | E25: 100000 | F25: 90 | I25: Comb Non | J25: Concerns that project is for trailhead parking when ample parking exists | K25: 7 | L25: Gwinnett
B26: Hogansville, City of | C26: Hogansville Water Tower Trail Phase IV | D26: 100000 | E26: 100000 | F26: 85 | I26: Comb Non | K26: 3 | L26: Troup
B27: Forsyth County | C27: Eagles Beak Park & Etowah River Trail Canoe Launch | D27: 100000 | E27: 100000 | F27: 80 | I27: Comb Non | K27: 9 | L27: Forsyth
B28: Lula, City of | C28: Nature Trails at Rafe Banks Park | D28: 100000 | E28: 91000 | F28: 80 | I28: Comb Non | K28: 9 | L28: Hall
B29: Camden County | C29: St. Mary's Tabby Trail - Sugar Mill Trailhead | D29: 97275.28 | E29: 97275.28 | F29: 75 | I29: Comb Non | K29: 1 | L29: Camden
B30: Lamar County | C30: North Lamar County Recreation Park Trail | D30: 100000 | E30: 100000 | F30: 75 | I30: Comb Non | K30: 3 | L30: Lamar
B31: Oxford, City of | C31: Oxford Connections Trail | D31: 100000 | E31: 100000 | F31: 75 | I31: Comb Non | J31: Local citizens have voiced concerns about trail in their backyard | K31: 4 | L31: Newton
B32: Murray County | C32: Veterans Memorial Park Multi-Purpose Trail | D32: 100000 | E32: 100000 | F32: 60 | I32: Comb Non | K32: 14 | L32: Murray
B33: Polk County | C33: Silver Comet Trail Maintenance Improvement | D33: 70362.66 | E33: 54362.66 | F33: 60 | I33: Comb Non | K33: 14 | L33: Polk
B34: Warner Robins, City of | C34: Healthy Community Trail #1 | D34: 80000 | E34: 80000 | F34: 60 | I34: Comb Non | K34: 8 | L34: Houston
B35: Effingham County | C35: Effingham County Recreation Complex Trail | D35: 100000 | E35: 100000 | F35: 55 | I35: Comb Non | K35: 12 | L35: Effingham
B36: Long County | C36: A Tile to Remember Trail | D36: 100000 | E36: 100000 | F36: 55 | I36: Comb Non | K36: 1 | L36: Long
B37: DNR - Mistletoe State Park | C37: Rock Dam Trail Bridge Construction & Replace Existing Footbridges | D37: 71200 | E37: 71200 | F37: 50 | I37: Comb Non | K37: 12 | L37: Columbia
B38: Putnam County | C38: Rock Hawk Recreational & Educational Trailhead Pavillion | D38: 33287.68 | E38: 33287.68 | F38: NE (130) | I38: Comb Non | J38: Not eligible - Application was bound. Concerns that trailhead pavillion is actually large outdoor classroom | K38: 10 | L38: Putnam
B39: Rockdale County | C39: Mountain Bike Trails at South Rockdale Community Park | D39: 100000 | E39: 100000 | F39: NE (115) | I39: Comb Non | J39: Not eligible - Application was bound. | K39: 4 | L39: Rockdale
B40: University of North Georgia | C40: Tumbling Creek Trail Restoration | D40: 75000 | E40: 75000 | F40: NE (115) | I40: Comb Non | J40: Ineligible - did not meet 20% match. Concerns about public access to university trails | K40: 9 | L40: Hall
...

Sheet Sheet1
A1: ='Main 2015'!$B$1 -> Project Sponsor | B1: ='Main 2015'!$C$1 -> Project Name | C1: ='Main 2015'!E1 -> Amt Approved | D1: ='Main 2015'!I1 -> Category | E1: ='Main 2015'!K1 -> District | F1: ='Main 2015'!L1 -> County
A2: ='Main 2015'!B2 -> Chattahoochee Hills, City of | B2: ='Main 2015'!C2 -> Trails of Chattahoochee Hills | C2: ='Main 2015'!E2 -> 100000 | D2: ='Main 2015'!I2 -> Comb Non | E2: ='Main 2015'!K2 -> 13 | F2: ='Main 2015'!L2 -> Fulton
A3: ='Main 2015'!B3 -> Georgia College & State University | B3: ='Main 2015'!C3 -> Fishing Creek Community Trail: Campus Connector | C3: ='Main 2015'!E3 -> 100000 | D3: ='Main 2015'!I3 -> Comb Non | E3: ='Main 2015'!K3 -> 10 | F3: ='Main 2015'!L3 -> Baldwin
A4: ='Main 2015'!B4 -> Perry, City of | B4: ='Main 2015'!C4 -> Big Indian Creek Waterway Trail Phase IV | C4: ='Main 2015'!E4 -> 100000 | D4: ='Main 2015'!I4 -> Comb Non | E4: ='Main 2015'!K4 -> 8 | F4: ='Main 2015'!L4 -> Houston
A5: ='Main 2015'!B5 -> Ringgold, City of | B5: ='Main 2015'!C5 -> Trail of Tears Phase II | C5: ='Main 2015'!E5 -> 100000 | D5: ='Main 2015'!I5 -> Comb Non | E5: ='Main 2015'!K5 -> 9 | F5: ='Main 2015'!L5 -> Catoosa
A6: ='Main 2015'!B6 -> Dawsonville, City of | B6: ='Main 2015'!C6 -> Main Street Park Trail | C6: ='Main 2015'!E6 -> 100000 | D6: ='Main 2015'!I6 -> Comb Non | E6: ='Main 2015'!K6 -> 9 | F6: ='Main 2015'!L6 -> Dawson
A7: ='Main 2015'!B7 -> Maxeys, City of | B7: ='Main 2015'!C7 -> Firefly Trail | C7: ='Main 2015'!E7 -> 100000 | D7: ='Main 2015'!I7 -> Comb Non | E7: ='Main 2015'!K7 -> 10 | F7: ='Main 2015'!L7 -> Oglethorpe
A8: ='Main 2015'!B8 -> Lee County | B8: ='Main 2015'!C8 -> Rails to Trails - Lee County Trailheads | C8: ='Main 2015'!E8 -> 100000 | D8: ='Main 2015'!I8 -> Comb Non | E8: ='Main 2015'!K8 -> 2 | F8: ='Main 2015'!L8 -> Lee
A9: ='Main 2015'!B9 -> White County | B9: ='Main 2015'!C9 -> Yonah Preserve Multi-Use Trail Phase II | C9: ='Main 2015'!E9 -> 100000 | D9: ='Main 2015'!I9 -> Comb Non | E9: ='Main 2015'!K9 -> 9 | F9: ='Main 2015'!L9 -> White
A10: ='Main 2015'!B10 -> Bibb County/City of Macon | B10: ='Main 2015'!C10 -> Amerson Water Works and Ocmulgee Heritage Trail Connector | C10: ='Main 2015'!E10 -> 92000 | D10: ='Main 2015'!I10 -> Comb Non | E10: ='Main 2015'!K10 -> 2 | F10: ='Main 2015'!L10 -> Macon/Bibb
A11: ='Main 2015'!B49 -> Bartow County | B11: ='Main 2015'!C49 -> The Etowah River Water Trail at Hardin Bridge | C11: ='Main 2015'!E49 -> 100000 | D11: ='Main 2015'!I49 -> Single Non | E11: ='Main 2015'!K49 -> 11 | F11: ='Main 2015'!L49 -> Bartow
A12: ='Main 2015'!B50 -> Lovejoy, City of | B12: ='Main 2015'!C50 -> Mayor's Park Trail | C12: ='Main 2015'!E50 -> 95040 | D12: ='Main 2015'!I50 -> Single Non | E12: ='Main 2015'!K50 -> 13 | F12: ='Main 2015'!L50 -> Clayton
A13: ='Main 2015'!B51 -> Lyons, City of | B13: ='Main 2015'!C51 -> Lyons Environmental Education Trail | C13: ='Main 2015'!E51 -> 56450 | D13: ='Main 2015'!I51 -> Single Non | E13: ='Main 2015'!K51 -> 12 | F13: ='Main 2015'!L51 -> Toombs

Sheet Summary
C1: Nonmotorized - Single Use | D1: Nonmotorized - Diversified | E1: Motorized
B3: Rollover funds from PY | C3: 271820.07 | D3: 105787.99 | E3: 1668233.8
A6: FY 2015 grant funds available | B6: 1722736
A7: 5% Education draw | B7: =B6*0.05 -> 86136.8
A8: 7% Admin draw | B8: =B6*0.07 -> 120591.52 | C8: 30% | D8: 40% | E8: 30%
A9: FY 2015 Balance for Projects | B9: =B6-B7-B8 -> 1516007.7 | C9: =B9*0.3 -> 454802.3 | D9: =B9*0.4 -> 606403.07 | E9: =B9*0.3 -> 454802.3
B11: PY plus CY Funds | C11: =C3+C9 -> 726622.37 | D11: =D3+D9 -> 712191.06 | E11: =E3+E9 -> 2123036.1
B13: Funds available from reverted projects (See below) | C13: 0 | D13: =C37 -> 209043.95 | E13: 0
B15: Total Funds Available | C15: =C11+C13 -> 726622.37 | D15: =D11+D13 -> 921235.01 | E15: =E11+E13 -> 2123036.1
B17: Total Funds Awarded 2015 | C17: =SUM('Main 2015'!G49:G51) -> 251490 | D17: =SUM('Main 2015'!G2:G10) -> 892000 | E17: 0
B18: Total Number of Projects Funded | C18: 3 | D18: 9 | E18: 0
B20: Unobligated Funds | C20: =C15-C17 -> 475132.37 | D20: =D15-D17 -> 29235.01 | E20: =E15-E17 -> 2123036.1
B29: Funds available from De and Re-obligated projects
C30: Available | D30: Project Number | E30: Source
B31: Chatham County | C31: 68259.9 | D31: 09(04) | E31: L940
B32: Carroll County | C32: 30996.65 | D32: 10(10) | E32: L94R
B33: Haralson County | C33: 11439.37 | D33: 09(08) | E33: L940R
B34: Vidalia | C34: 748.03 | D34: 09(14) | E34: L940
B35: Euharlee, City of | C35: 97600 | D35: 12(14) | E35: L94E
B37: Total Allocated to Nonmotorized - Diversified | C37: =SUM(C31:C36) -> 209043.95
